Workbook
Name Slicer_City: #N/A
Name Slicer_Company: #N/A
Name Slicer_Country: #N/A
Name Timeline_Subscription_Date: #N/A

Sheet Questions
A1: Questions
A2: 1. Create a new sheet called employee_details with these new columns (employeeID , department, First Name, Last Name, City, Company, country, Subscription Date, Year of subscription)
A3: 2. Create a pivot table with the following columns (Country, city, Number of distinct employees)
A4: 3. In a graph show total number of customers by city and country
A5: 4. What Company, city and country has the most employes? Show how you arrived at this.
A6: 5. Highlight duplicated first and last name employees in the sheet employees
A7: 6. In what year did employees subscribe the most?
A8: 7. Create an excel Dashboard showing some of the mertics.

Sheet Dashboard

Sheet employee by city and country
A3: Row Labels | B3: Count of employeeID
A4: Canada
A5: Vancouver | B5: 43
A6: Toronto | B6: 42
A7: Montreal | B7: 33
A8: Australia
A9: Brisbane | B9: 43
A10: Melbourne | B10: 36
A11: Sydney | B11: 30
A12: Germany
A13: Munich | B13: 43
A14: Berlin | B14: 31
A15: Hamburg | B15: 31
A16: United Kingdom
A17: London | B17: 45
A18: Birmingham | B18: 31
A19: Manchester | B19: 25
A20: Brazil
A21: Brasilia | B21: 35
A22: Rio de Janeiro | B22: 35
A23: Sao Paulo | B23: 29
A24: France
A25: Paris | B25: 36
A26: Lyon | B26: 33
A27: Marseille | B27: 30
A28: Russia
A29: St. Petersburg | B29: 38
A30: Moscow | B30: 30
A31: Novosibirsk | B31: 30
A32: United States
A33: Los Angeles | B33: 35
A34: Chicago | B34: 34
A35: New York | B35: 26
A36: India
A37: Mumbai | B37: 33
A38: Bangalore | B38: 28
A39: New Delhi | B39: 27
A40: China
A41: Shanghai | B41: 32
A42: Beijing | B42: 28
...

Sheet companycitycountrymostemployess
A3: Row Labels | B3: Distinct Count of employeeID
A4: NexusByte Innovations | B4: 69
A5: PhoenixRise Technologies | B5: 60
A6: CoreNex Corporation | B6: 57
A7: ThunderByte Ventures | B7: 56
A8: OptiCore Systems | B8: 56
A9: CrystalWave Solutions | B9: 53
A10: MarvellaTech Solutions | B10: 52
A11: PrimeWave Solutions | B11: 51
A12: BlueSky Innovations | B12: 50
A13: FusionQuest Industries | B13: 49
A14: StellarWorks Co. | B14: 49
A15: EonCore Ventures | B15: 49
... A24: Grand Total | B24: 1000

Sheet mostsubscriptionyear
A3: Row Labels | B3: Distinct Count of employeeID
A4: 2020 | B4: 426
A5: 2021 | B5: 404
A6: 2022 | B6: 170
A7: Grand Total | B7: 1000

Sheet Total Employee
A3: Distinct Count of employeeID
A4: 1000

Sheet Top Department
A3: Row Labels | B3: Distinct Count of employeeID
A4: Human Resources Development | B4: 115
A5: Research and Development | B5: 113
A6: Sustainability Initiatives | B6: 106
A7: Financial Planning | B7: 103
A8: Data Analytics | B8: 101
A9: Quality Assurance | B9: 98
A10: Customer Experience | B10: 96
A11: Operations Optimization | B11: 92
A12: Product Innovation | B12: 90
A13: Marketing Strategies | B13: 86
A14: Grand Total | B14: 1000

Sheet employee by country
A3: Row Labels | B3: Count of employeeID
A4: Australia | B4: 109
A5: Brazil | B5: 99
A6: Canada | B6: 118
A7: China | B7: 88
A8: France | B8: 99
A9: Germany | B9: 105
A10: India | B10: 88
A11: Russia | B11: 98
A12: United Kingdom | B12: 101
A13: United States | B13: 95
A14: Grand Total | B14: 1000

Sheet employee by city
A3: Row Labels | B3: Count of employeeID
A4: Bangalore | B4: 28
A5: Beijing | B5: 28
A6: Berlin | B6: 31
A7: Birmingham | B7: 31
A8: Brasilia | B8: 35
A9: Brisbane | B9: 43
A10: Chicago | B10: 34
A11: Guangzhou | B11: 28
A12: Hamburg | B12: 31
A13: London | B13: 45
A14: Los Angeles | B14: 35
A15: Lyon | B15: 33
... A34: Grand Total | B34: 1000

Sheet employee by company
A3: Row Labels | B3: Count of employeeID
A4: AlphaGenix Labs | B4: 48
A5: BlueSky Innovations | B5: 50
A6: CoreNex Corporation | B6: 57
A7: CrystalWave Solutions | B7: 53
A8: EonCore Ventures | B8: 49
A9: FusionQuest Industries | B9: 49
A10: HorizonShift Systems | B10: 43
A11: MarvellaTech Solutions | B11: 52
A12: NexusByte Innovations | B12: 69
A13: OptiCore Systems | B13: 56
A14: PhoenixRise Technologies | B14: 60
A15: PrimeWave Solutions | B15: 51
... A24: Grand Total | B24: 1000

Sheet employee_details
A1: employeeID | B1: Department | C1: First Name | D1: Last Name | E1: City | F1: Company | G1: Country | H1: Subscription Date | I1: Year of Subscription
A2: {=employee_company!A2:A1001} -> dE014d010c7ab0c | B2: =_xlfn.XLOOKUP(_xlfn.XLOOKUP(A2, employees!B:B, employees!E:E), department!A:A, department!B:B) -> Customer Experience | C2: =_xlfn.XLOOKUP(A2, employees!B:B, employees!C:C) -> Andrew | D2: =_xlfn.XLOOKUP(A2, employees!B:B, employees!D:D) -> Goodman | E2: =_xlfn.XLOOKUP(A2, employee_country!D:D, employee_country!B:B) -> Moscow | F2: =_xlfn.XLOOKUP(A2, employee_company!A:A, employee_company!B:B) -> AlphaGenix Labs | G2: =_xlfn.XLOOKUP(A2, employee_country!D:D, employee_country!C:C) -> Russia | H2: =_xlfn.XLOOKUP(A2, employee_company!A:A, employee_company!C:C) -> 44403 | I2: =YEAR(H2) -> 2021
A3: 2B54172c8b65eC3 | B3: =_xlfn.XLOOKUP(_xlfn.XLOOKUP(A3, employees!B:B, employees!E:E), department!A:A, department!B:B) -> Financial Planning | C3: =_xlfn.XLOOKUP(A3, employees!B:B, employees!C:C) -> Alvin | D3: =_xlfn.XLOOKUP(A3, employees!B:B, employees!D:D) -> Lane | E3: =_xlfn.XLOOKUP(A3, employee_country!D:D, employee_country!B:B) -> Brasilia | F3: =_xlfn.XLOOKUP(A3, employee_company!A:A, employee_company!B:B) -> SunCrest Industries | G3: =_xlfn.XLOOKUP(A3, employee_country!D:D, employee_country!C:C) -> Brazil | H3: =_xlfn.XLOOKUP(A3, employee_company!A:A, employee_company!C:C) -> 44371 | I3: =YEAR(H3) -> 2021
A4: d794Dd48988d2ac | B4: =_xlfn.XLOOKUP(_xlfn.XLOOKUP(A4, employees!B:B, employees!E:E), department!A:A, department!B:B) -> Marketing Strategies | C4: =_xlfn.XLOOKUP(A4, employees!B:B, employees!C:C) -> Jenna | D4: =_xlfn.XLOOKUP(A4, employees!B:B, employees!D:D) -> Harding | E4: =_xlfn.XLOOKUP(A4, employee_country!D:D, employee_country!B:B) -> Chicago | F4: =_xlfn.XLOOKUP(A4, employee_company!A:A, employee_company!B:B) -> QuantumSpark Labs | G4: =_xlfn.XLOOKUP(A4, employee_country!D:D, employee_country!C:C) -> United States | H4: =_xlfn.XLOOKUP(A4, employee_company!A:A, employee_company!C:C) -> 43926 | I4: =YEAR(H4) -> 2020
A5: 3b3Aa4aCc68f3Be | B5: =_xlfn.XLOOKUP(_xlfn.XLOOKUP(A5, employees!B:B, employees!E:E), department!A:A, department!B:B) -> Marketing Strategies | C5: =_xlfn.XLOOKUP(A5, employees!B:B, employees!C:C) -> Fernando | D5: =_xlfn.XLOOKUP(A5, employees!B:B, employees!D:D) -> Ford | E5: =_xlfn.XLOOKUP(A5, employee_country!D:D, employee_country!B:B) -> London | F5: =_xlfn.XLOOKUP(A5, employee_company!A:A, employee_company!B:B) -> CoreNex Corporation | G5: =_xlfn.XLOOKUP(A5, employee_country!D:D, employee_country!C:C) -> United Kingdom | H5: =_xlfn.XLOOKUP(A5, employee_company!A:A, employee_company!C:C) -> 44164 | I5: =YEAR(H5) -> 2020
A6: D60df62ad2ae41E | B6: =_xlfn.XLOOKUP(_xlfn.XLOOKUP(A6, employees!B:B, employees!E:E), department!A:A, department!B:B) -> Human Resources Development | C6: =_xlfn.XLOOKUP(A6, employees!B:B, employees!C:C) -> Kara | D6: =_xlfn.XLOOKUP(A6, employees!B:B, employees!D:D) -> Woods | E6: =_xlfn.XLOOKUP(A6, employee_country!D:D, employee_country!B:B) -> Berlin | F6: =_xlfn.XLOOKUP(A6, employee_company!A:A, employee_company!B:B) -> PhoenixRise Technologies | G6: =_xlfn.XLOOKUP(A6, employee_country!D:D, employee_country!C:C) -> Germany | H6: =_xlfn.XLOOKUP(A6, employee_company!A:A, employee_company!C:C) -> 44673 | I6: =YEAR(H6) -> 2022
A7: 8aaa5d0CE9ee311 | B7: =_xlfn.XLOOKUP(_xlfn.XLOOKUP(A7, employees!B:B, employees!E:E), department!A:A, department!B:B) -> Quality Assurance | C7: =_xlfn.XLOOKUP(A7, employees!B:B, employees!C:C) -> Marissa | D7: =_xlfn.XLOOKUP(A7, employees!B:B, employees!D:D) -> Gamble | E7: =_xlfn.XLOOKUP(A7, employee_country!D:D, employee_country!B:B) -> Marseille | F7: =_xlfn.XLOOKUP(A7, employee_company!A:A, employee_company!B:B) -> OptiCore Systems | G7: =_xlfn.XLOOKUP(A7, employee_country!D:D, employee_country!C:C) -> France | H7: =_xlfn.XLOOKUP(A7, employee_company!A:A, employee_company!C:C) -> 44517 | I7: =YEAR(H7) -> 2021
A8: 73B22Ac8A43DD1A | B8: =_xlfn.XLOOKUP(_xlfn.XLOOKUP(A8, employees!B:B, employees!E:E), department!A:A, department!B:B) -> Customer Experience | C8: =_xlfn.XLOOKUP(A8, employees!B:B, employees!C:C) -> Julie | D8: =_xlfn.XLOOKUP(A8, employees!B:B, employees!D:D) -> Cooley | E8: =_xlfn.XLOOKUP(A8, employee_country!D:D, employee_country!B:B) -> New Delhi | F8: =_xlfn.XLOOKUP(A8, employee_company!A:A, employee_company!B:B) -> SilverPeak Dynamics | G8: =_xlfn.XLOOKUP(A8, employee_country!D:D, employee_country!C:C) -> India | H8: =_xlfn.XLOOKUP(A8, employee_company!A:A, employee_company!C:C) -> 44646 | I8: =YEAR(H8) -> 2022
A9: DC94CCd993D311b | B9: =_xlfn.XLOOKUP(_xlfn.XLOOKUP(A9, employees!B:B, employees!E:E), department!A:A, department!B:B) -> Human Resources Development | C9: =_xlfn.XLOOKUP(A9, employees!B:B, employees!C:C) -> Lauren | D9: =_xlfn.XLOOKUP(A9, employees!B:B, employees!D:D) -> Villa | E9: =_xlfn.XLOOKUP(A9, employee_country!D:D, employee_country!B:B) -> Bangalore | F9: =_xlfn.XLOOKUP(A9, employee_company!A:A, employee_company!B:B) -> AlphaGenix Labs | G9: =_xlfn.XLOOKUP(A9, employee_country!D:D, employee_country!C:C) -> India | H9: =_xlfn.XLOOKUP(A9, employee_company!A:A, employee_company!C:C) -> 44057 | I9: =YEAR(H9) -> 2020
A10: 9Ba746Cb790FED9 | B10: =_xlfn.XLOOKUP(_xlfn.XLOOKUP(A10, employees!B:B, employees!E:E), department!A:A, department!B:B) -> Research and Development | C10: =_xlfn.XLOOKUP(A10, employees!B:B, employees!C:C) -> Emily | D10: =_xlfn.XLOOKUP(A10, employees!B:B, employees!D:D) -> Bryant | E10: =_xlfn.XLOOKUP(A10, employee_country!D:D, employee_country!B:B) -> Sao Paulo | F10: =_xlfn.XLOOKUP(A10, employee_company!A:A, employee_company!B:B) -> BlueSky Innovations | G10: =_xlfn.XLOOKUP(A10, employee_country!D:D, employee_country!C:C) -> Brazil | H10: =_xlfn.XLOOKUP(A10, employee_company!A:A, employee_company!C:C) -> 44195 | I10: =YEAR(H10) -> 2020
A11: aAa1EDfaA70DA0c | B11: =_xlfn.XLOOKUP(_xlfn.XLOOKUP(A11, employees!B:B, employees!E:E), department!A:A, department!B:B) -> Financial Planning | C11: =_xlfn.XLOOKUP(A11, employees!B:B, employees!C:C) -> Marie | D11: =_xlfn.XLOOKUP(A11, employees!B:B, employees!D:D) -> Estrada | E11: =_xlfn.XLOOKUP(A11, employee_country!D:D, employee_country!B:B) -> Birmingham | F11: =_xlfn.XLOOKUP(A11, employee_company!A:A, employee_company!B:B) -> ThunderByte Ventures | G11: =_xlfn.XLOOKUP(A11, employee_country!D:D, employee_country!C:C) -> United Kingdom | H11: =_xlfn.XLOOKUP(A11, employee_company!A:A, employee_company!C:C) -> 44077 | I11: =YEAR(H11) -> 2020
A12: bf104C25d0BA4E1 | B12: =_xlfn.XLOOKUP(_xlfn.XLOOKUP(A12, employees!B:B, employees!E:E), department!A:A, department!B:B) -> Data Analytics | C12: =_xlfn.XLOOKUP(A12, employees!B:B, employees!C:C) -> Nichole | D12: =_xlfn.XLOOKUP(A12, employees!B:B, employees!D:D) -> Cannon | E12: =_xlfn.XLOOKUP(A12, employee_country!D:D, employee_country!B:B) -> Brasilia | F12: =_xlfn.XLOOKUP(A12, employee_company!A:A, employee_company!B:B) -> NexusByte Innovations | G12: =_xlfn.XLOOKUP(A12, employee_country!D:D, employee_country!C:C) -> Brazil | H12: =_xlfn.XLOOKUP(A12, employee_company!A:A, employee_company!C:C) -> 44312 | I12: =YEAR(H12) -> 2021
A13: bf2fA37cbAd7dDc | B13: =_xlfn.XLOOKUP(_xlfn.XLOOKUP(A13, employees!B:B, employees!E:E), department!A:A, department!B:B) -> Research and Development | C13: =_xlfn.XLOOKUP(A13, employees!B:B, employees!C:C) -> Bernard | D13: =_xlfn.XLOOKUP(A13, employees!B:B, employees!D:D) -> Ritter | E13: =_xlfn.XLOOKUP(A13, employee_country!D:D, employee_country!B:B) -> Munich | F13: =_xlfn.XLOOKUP(A13, employee_company!A:A, employee_company!B:B) -> CrystalWave Solutions | G13: =_xlfn.XLOOKUP(A13, employee_country!D:D, employee_country!C:C) -> Germany | H13: =_xlfn.XLOOKUP(A13, employee_company!A:A, employee_company!C:C) -> 44580 | I13: =YEAR(H13) -> 2022
A14: 4fa8ffcdBbf53bB | B14: =_xlfn.XLOOKUP(_xlfn.XLOOKUP(A14, employees!B:B, employees!E:E), department!A:A, department!B:B) -> Research and Development | C14: =_xlfn.XLOOKUP(A14, employees!B:B, employees!C:C) -> Darryl | D14: =_xlfn.XLOOKUP(A14, employees!B:B, employees!D:D) -> Archer | E14: =_xlfn.XLOOKUP(A14, employee_country!D:D, employee_country!B:B) -> Berlin | F14: =_xlfn.XLOOKUP(A14, employee_company!A:A, employee_company!B:B) -> StellarWorks Co. | G14: =_xlfn.XLOOKUP(A14, employee_country!D:D, employee_country!C:C) -> Germany | H14: =_xlfn.XLOOKUP(A14, employee_company!A:A, employee_company!C:C) -> 44669 | I14: =YEAR(H14) -> 2022
... A1001: 51732B5b2328015 | B1001: =_xlfn.XLOOKUP(_xlfn.XLOOKUP(A1001, employees!B:B, employees!E:E), department!A:A, department!B:B) -> Marketing Strategies | C1001: =_xlfn.XLOOKUP(A1001, employees!B:B, employees!C:C) -> Dominic | D1001: =_xlfn.XLOOKUP(A1001, employees!B:B, employees!D:D) -> Duran | E1001: =_xlfn.XLOOKUP(A1001, employee_country!D:D, employee_country!B:B) -> Rio de Janeiro | F1001: =_xlfn.XLOOKUP(A1001, employee_company!A:A, employee_company!B:B) -> BlueSky Innovations | G1001: =_xlfn.XLOOKUP(A1001, employee_country!D:D, employee_country!C:C) -> Brazil | H1001: =_xlfn.XLOOKUP(A1001, employee_company!A:A, employee_company!C:C) -> 44539 | I1001: =YEAR(H1001) -> 2021

Sheet employees
A1: Index | B1: employeeID | C1: First Name | D1: Last Name | E1: DepartmentID
A2: 1 | B2: dE014d010c7ab0c | C2: Andrew | D2: Goodman | E2: 2
A3: 2 | B3: 2B54172c8b65eC3 | C3: Alvin | D3: Lane | E3: 7
A4: 3 | B4: d794Dd48988d2ac | C4: Jenna | D4: Harding | E4: 5
A5: 4 | B5: 3b3Aa4aCc68f3Be | C5: Fernando | D5: Ford | E5: 5
A6: 5 | B6: D60df62ad2ae41E | C6: Kara | D6: Woods | E6: 6
A7: 6 | B7: 8aaa5d0CE9ee311 | C7: Marissa | D7: Gamble | E7: 9
A8: 7 | B8: 73B22Ac8A43DD1A | C8: Julie | D8: Cooley | E8: 2
A9: 8 | B9: DC94CCd993D311b | C9: Lauren | D9: Villa | E9: 6
A10: 9 | B10: 9Ba746Cb790FED9 | C10: Emily | D10: Bryant | E10: 8
A11: 10 | B11: aAa1EDfaA70DA0c | C11: Marie | D11: Estrada | E11: 7
A12: 11 | B12: bf104C25d0BA4E1 | C12: Nichole | D12: Cannon | E12: 3
A13: 12 | B13: bf2fA37cbAd7dDc | C13: Bernard | D13: Ritter | E13: 8
... A1001: 1000 | B1001: 51732B5b2328015 | C1001: Dominic | D1001: Duran | E1001: 5

Sheet department
A1: DepartmentID | B1: Department
A2: 1 | B2: Product Innovation
A3: 2 | B3: Customer Experience
A4: 3 | B4: Data Analytics
A5: 4 | B5: Operations Optimization
A6: 5 | B6: Marketing Strategies
A7: 6 | B7: Human Resources Development
A8: 7 | B8: Financial Planning
A9: 8 | B9: Research and Development
A10: 9 | B10: Quality Assurance
A11: 10 | B11: Sustainability Initiatives

Sheet employee_company
A1: employeeID | B1: Company | C1: Subscription Date
A2: dE014d010c7ab0c | B2: AlphaGenix Labs | C2: 44403
A3: 2B54172c8b65eC3 | B3: SunCrest Industries | C3: 44371
A4: d794Dd48988d2ac | B4: QuantumSpark Labs | C4: 43926
A5: 3b3Aa4aCc68f3Be | B5: CoreNex Corporation | C5: 44164
A6: D60df62ad2ae41E | B6: PhoenixRise Technologies | C6: 44673
A7: 8aaa5d0CE9ee311 | B7: OptiCore Systems | C7: 44517
A8: 73B22Ac8A43DD1A | B8: SilverPeak Dynamics | C8: 44646
A9: DC94CCd993D311b | B9: AlphaGenix Labs | C9: 44057
A10: 9Ba746Cb790FED9 | B10: BlueSky Innovations | C10: 44195
A11: aAa1EDfaA70DA0c | B11: ThunderByte Ventures | C11: 44077
A12: bf104C25d0BA4E1 | B12: NexusByte Innovations | C12: 44312
A13: bf2fA37cbAd7dDc | B13: CrystalWave Solutions | C13: 44580
... A1001: 51732B5b2328015 | B1001: BlueSky Innovations | C1001: 44539

Sheet employee_country
A1: Index | B1: City | C1: Country | D1: employeeID
A2: 1 | B2: Moscow | C2: Russia | D2: dE014d010c7ab0c
A3: 2 | B3: Brasilia | C3: Brazil | D3: 2B54172c8b65eC3
A4: 3 | B4: Chicago | C4: United States | D4: d794Dd48988d2ac
A5: 4 | B5: London | C5: United Kingdom | D5: 3b3Aa4aCc68f3Be
A6: 5 | B6: Berlin | C6: Germany | D6: D60df62ad2ae41E
A7: 6 | B7: Marseille | C7: France | D7: 8aaa5d0CE9ee311
A8: 7 | B8: New Delhi | C8: India | D8: 73B22Ac8A43DD1A
A9: 8 | B9: Bangalore | C9: India | D9: DC94CCd993D311b
A10: 9 | B10: Sao Paulo | C10: Brazil | D10: 9Ba746Cb790FED9
A11: 10 | B11: Birmingham | C11: United Kingdom | D11: aAa1EDfaA70DA0c
A12: 11 | B12: Brasilia | C12: Brazil | D12: bf104C25d0BA4E1
A13: 12 | B13: Munich | C13: Germany | D13: bf2fA37cbAd7dDc
... A1001: 1000 | B1001: Rio de Janeiro | C1001: Brazil | D1001: 51732B5b2328015
